# SOME DESCRIPTIVE TITLE.
# Copyright (C) 2001-2023, Python Software Foundation
# This file is distributed under the same license as the Python package.
# FIRST AUTHOR <EMAIL@ADDRESS>, YEAR.
#
# Translators:
# ww song <sww4718168@gmail.com>, 2019
# ppcfish <ppcfish@gmail.com>, 2019
#
#, fuzzy
msgid ""
msgstr ""
"Project-Id-Version: Python 3.7\n"
"Report-Msgid-Bugs-To: \n"
"POT-Creation-Date: 2023-06-16 16:41+0000\n"
"PO-Revision-Date: 2019-09-01 03:31+0000\n"
"Last-Translator: ppcfish <ppcfish@gmail.com>, 2019\n"
"Language-Team: Chinese (China) (https://app.transifex.com/python-doc/"
"teams/5390/zh_CN/)\n"
"MIME-Version: 1.0\n"
"Content-Type: text/plain; charset=UTF-8\n"
"Content-Transfer-Encoding: 8bit\n"
"Language: zh_CN\n"
"Plural-Forms: nplurals=1; plural=0;\n"

#: /home/runner/work/python-docs-tx-translations/python-docs-tx-translations/cpython/Doc/library/asyncio-exceptions.rst:8
msgid "Exceptions"
msgstr "异常"

#: /home/runner/work/python-docs-tx-translations/python-docs-tx-translations/cpython/Doc/library/asyncio-exceptions.rst:13
msgid "The operation has exceeded the given deadline."
msgstr "该操作已超过规定的截止日期。"

#: /home/runner/work/python-docs-tx-translations/python-docs-tx-translations/cpython/Doc/library/asyncio-exceptions.rst:16
msgid ""
"This exception is different from the builtin :exc:`TimeoutError` exception."
msgstr "这个异常与内置 :exc:`TimeoutError` 异常不同。"

#: /home/runner/work/python-docs-tx-translations/python-docs-tx-translations/cpython/Doc/library/asyncio-exceptions.rst:22
msgid "The operation has been cancelled."
msgstr "该操作已被取消。"

#: /home/runner/work/python-docs-tx-translations/python-docs-tx-translations/cpython/Doc/library/asyncio-exceptions.rst:24
msgid ""
"This exception can be caught to perform custom operations when asyncio Tasks "
"are cancelled.  In almost all situations the exception must be re-raised."
msgstr ""
"取消asyncio任务时，可以捕获此异常以执行自定义操作。在几乎所有情况下，都必须重"
"新引发异常。"

#: /home/runner/work/python-docs-tx-translations/python-docs-tx-translations/cpython/Doc/library/asyncio-exceptions.rst:30
msgid ""
"This exception is a subclass of :exc:`Exception`, so it can be accidentally "
"suppressed by an overly broad ``try..except`` block::"
msgstr ""
"此异常是 :exc:`Exception` 的子类，因此可能会被一个过于宽泛的 ``try..except`` "
"块意外地阻塞："

#: /home/runner/work/python-docs-tx-translations/python-docs-tx-translations/cpython/Doc/library/asyncio-exceptions.rst:40
msgid "Instead, the following pattern should be used::"
msgstr "相反，应使用以下模式::"

#: /home/runner/work/python-docs-tx-translations/python-docs-tx-translations/cpython/Doc/library/asyncio-exceptions.rst:52
msgid "Invalid internal state of :class:`Task` or :class:`Future`."
msgstr ":class:`Task` 或 :class:`Future` 的内部状态无效。"

#: /home/runner/work/python-docs-tx-translations/python-docs-tx-translations/cpython/Doc/library/asyncio-exceptions.rst:54
msgid ""
"Can be raised in situations like setting a result value for a *Future* "
"object that already has a result value set."
msgstr "在为已设置结果值的未来对象设置结果值等情况下，可以引发此问题。"

#: /home/runner/work/python-docs-tx-translations/python-docs-tx-translations/cpython/Doc/library/asyncio-exceptions.rst:60
msgid ""
"The \"sendfile\" syscall is not available for the given socket or file type."
msgstr "\"sendfile\" 系统调用不适用于给定的套接字或文件类型。"

#: /home/runner/work/python-docs-tx-translations/python-docs-tx-translations/cpython/Doc/library/asyncio-exceptions.rst:63
msgid "A subclass of :exc:`RuntimeError`."
msgstr "子类 :exc:`RuntimeError` 。"

#: /home/runner/work/python-docs-tx-translations/python-docs-tx-translations/cpython/Doc/library/asyncio-exceptions.rst:68
msgid "The requested read operation did not complete fully."
msgstr "请求的读取操作未完全完成。"

#: /home/runner/work/python-docs-tx-translations/python-docs-tx-translations/cpython/Doc/library/asyncio-exceptions.rst:70
msgid "Raised by the :ref:`asyncio stream APIs<asyncio-streams>`."
msgstr "由 :ref:`asyncio stream APIs<asyncio-streams>` 提出"

#: /home/runner/work/python-docs-tx-translations/python-docs-tx-translations/cpython/Doc/library/asyncio-exceptions.rst:72
msgid "This exception is a subclass of :exc:`EOFError`."
msgstr "此异常是 :exc:`EOFError` 的子类。"

#: /home/runner/work/python-docs-tx-translations/python-docs-tx-translations/cpython/Doc/library/asyncio-exceptions.rst:76
msgid "The total number (:class:`int`) of expected bytes."
msgstr "预期字节的总数（ :class:`int` ）。"

#: /home/runner/work/python-docs-tx-translations/python-docs-tx-translations/cpython/Doc/library/asyncio-exceptions.rst:80
msgid "A string of :class:`bytes` read before the end of stream was reached."
msgstr "到达流结束之前读取的 :class:`bytes` 字符串。"

#: /home/runner/work/python-docs-tx-translations/python-docs-tx-translations/cpython/Doc/library/asyncio-exceptions.rst:85
msgid "Reached the buffer size limit while looking for a separator."
msgstr "在查找分隔符时达到缓冲区大小限制。"

#: /home/runner/work/python-docs-tx-translations/python-docs-tx-translations/cpython/Doc/library/asyncio-exceptions.rst:87
msgid "Raised by the :ref:`asyncio stream APIs <asyncio-streams>`."
msgstr "由 :ref:`asyncio stream APIs <asyncio-streams>` 提出"

#: /home/runner/work/python-docs-tx-translations/python-docs-tx-translations/cpython/Doc/library/asyncio-exceptions.rst:91
msgid "The total number of to be consumed bytes."
msgstr "要消耗的字节总数。"
