# SOME DESCRIPTIVE TITLE.
# Copyright (C) 2001-2024, Python Software Foundation
# This file is distributed under the same license as the Python package.
# FIRST AUTHOR <EMAIL@ADDRESS>, YEAR.
#
# Translators:
# Alpha Du <alphanow@gmail.com>, 2020
# Freesand Leo <yuqinju@163.com>, 2021
# Rafael Fontenelle <rffontenelle@gmail.com>, 2023
#
#, fuzzy
msgid ""
msgstr ""
"Project-Id-Version: Python 3.8\n"
"Report-Msgid-Bugs-To: \n"
"POT-Creation-Date: 2024-01-13 00:12+0000\n"
"PO-Revision-Date: 2020-05-30 12:02+0000\n"
"Last-Translator: Rafael Fontenelle <rffontenelle@gmail.com>, 2023\n"
"Language-Team: Chinese (China) (https://app.transifex.com/python-doc/"
"teams/5390/zh_CN/)\n"
"MIME-Version: 1.0\n"
"Content-Type: text/plain; charset=UTF-8\n"
"Content-Transfer-Encoding: 8bit\n"
"Language: zh_CN\n"
"Plural-Forms: nplurals=1; plural=0;\n"

#: ../../library/exceptions.rst:4
msgid "Built-in Exceptions"
msgstr "内置异常"

#: ../../library/exceptions.rst:10
msgid ""
"In Python, all exceptions must be instances of a class that derives from :"
"class:`BaseException`.  In a :keyword:`try` statement with an :keyword:"
"`except` clause that mentions a particular class, that clause also handles "
"any exception classes derived from that class (but not exception classes "
"from which *it* is derived).  Two exception classes that are not related via "
"subclassing are never equivalent, even if they have the same name."
msgstr ""
"在 Python 中，所有异常必须为一个派生自 :class:`BaseException` 的类的实例。 在"
"带有提及一个特定类的 :keyword:`except` 子句的 :keyword:`try` 语句中，该子句也"
"会处理任何派生自该类的异常类（但不处理 *它* 所派生出的异常类）。 通过子类化创"
"建的两个不相关异常类永远是不等效的，既使它们具有相同的名称。"

#: ../../library/exceptions.rst:19
msgid ""
"The built-in exceptions listed below can be generated by the interpreter or "
"built-in functions.  Except where mentioned, they have an \"associated "
"value\" indicating the detailed cause of the error.  This may be a string or "
"a tuple of several items of information (e.g., an error code and a string "
"explaining the code).  The associated value is usually passed as arguments "
"to the exception class's constructor."
msgstr ""
"下面列出的内置异常可通过解释器或内置函数来生成。除非另有说明，它们都会具有一"
"个提示导致错误详细原因的“关联值”。 这可以是一个字符串或由多个信息项（例如一个"
"错误码和一个解释错误的字符串）组成的元组。 关联值通常会作为参数被传递给异常类"
"的构造器。"

#: ../../library/exceptions.rst:26
msgid ""
"User code can raise built-in exceptions.  This can be used to test an "
"exception handler or to report an error condition \"just like\" the "
"situation in which the interpreter raises the same exception; but beware "
"that there is nothing to prevent user code from raising an inappropriate "
"error."
msgstr ""
"用户代码可以引发内置异常。 这可被用于测试异常处理程序或报告错误条件，“就像” "
"在解释器引发了相同异常的情况时一样；但是请注意，没有任何机制能防止用户代码引"
"发不适当的错误。"

#: ../../library/exceptions.rst:31
msgid ""
"The built-in exception classes can be subclassed to define new exceptions; "
"programmers are encouraged to derive new exceptions from the :exc:"
"`Exception` class or one of its subclasses, and not from :exc:"
"`BaseException`.  More information on defining exceptions is available in "
"the Python Tutorial under :ref:`tut-userexceptions`."
msgstr ""
"内置异常类可以被子类化以定义新的异常；鼓励程序员从 :exc:`Exception` 类或它的"
"某个子类而不是从 :exc:`BaseException` 来派生新的异常。 关于定义异常的更多信息"
"可以在 Python 教程的 :ref:`tut-userexceptions` 部分查看。"

#: ../../library/exceptions.rst:37
msgid ""
"When raising (or re-raising) an exception in an :keyword:`except` or :"
"keyword:`finally` clause :attr:`__context__` is automatically set to the "
"last exception caught; if the new exception is not handled the traceback "
"that is eventually displayed will include the originating exception(s) and "
"the final exception."
msgstr ""
"当在 :keyword:`except` 或 :keyword:`finally` 子句中引发（或重新引发）异常"
"时，:attr:`__context__` 会被自动设为所捕获的最后一个异常；如果新的异常未被处"
"理，则最终显示的回溯信息将包括原始的异常和最后的异常。"

#: ../../library/exceptions.rst:43
msgid ""
"When raising a new exception (rather than using a bare ``raise`` to re-raise "
"the exception currently being handled), the implicit exception context can "
"be supplemented with an explicit cause by using :keyword:`from<raise>` with :"
"keyword:`raise`::"
msgstr ""
"当引发一个新的异常（而不是简单地使用 ``raise`` 来重新引发 当前在处理的异常）"
"时，隐式的异常上下文可以通过使用带有 :keyword:`raise` 的 :keyword:"
"`from<raise>` 子句来补充一个显式的原因::"

#: ../../library/exceptions.rst:50
msgid ""
"The expression following :keyword:`from<raise>` must be an exception or "
"``None``. It will be set as :attr:`__cause__` on the raised exception. "
"Setting :attr:`__cause__` also implicitly sets the :attr:"
"`__suppress_context__` attribute to ``True``, so that using ``raise new_exc "
"from None`` effectively replaces the old exception with the new one for "
"display purposes (e.g. converting :exc:`KeyError` to :exc:`AttributeError`), "
"while leaving the old exception available in :attr:`__context__` for "
"introspection when debugging."
msgstr ""
"跟在 :keyword:`from<raise>` 之后一表达式必须为一个异常或 ``None``。 它将在所"
"引发的异常上被设置为 :attr:`__cause__`。 设置 :attr:`__cause__` 还会隐式地"
"将 :attr:`__suppress_context__` 属性设为 ``True``，这样使用 ``raise new_exc "
"from None`` 可以有效地将旧异常替换为新异常来显示其目的 (例如将 :exc:"
"`KeyError` 转换为 :exc:`AttributeError`)，同时让旧异常在 :attr:`__context__` "
"中保持可用状态以便在调试时进行内省。"

#: ../../library/exceptions.rst:59
msgid ""
"The default traceback display code shows these chained exceptions in "
"addition to the traceback for the exception itself. An explicitly chained "
"exception in :attr:`__cause__` is always shown when present. An implicitly "
"chained exception in :attr:`__context__` is shown only if :attr:`__cause__` "
"is :const:`None` and :attr:`__suppress_context__` is false."
msgstr ""
"除了异常本身的回溯以外，默认的回溯还会显示这些串连的异常。 :attr:`__cause__` "
"中的显式串连异常如果存在将总是显示。 :attr:`__context__` 中的隐式串连异常仅"
"在 :attr:`__cause__` 为 :const:`None` 并且 :attr:`__suppress_context__` 为假"
"值时显示。"

#: ../../library/exceptions.rst:65
msgid ""
"In either case, the exception itself is always shown after any chained "
"exceptions so that the final line of the traceback always shows the last "
"exception that was raised."
msgstr ""
"不论在哪种情况下，异常本身总会在任何串连异常之后显示，以便回溯的最后一行总是"
"显示所引发的最后一个异常。"

#: ../../library/exceptions.rst:71
msgid "Base classes"
msgstr "基类"

#: ../../library/exceptions.rst:73
msgid ""
"The following exceptions are used mostly as base classes for other "
"exceptions."
msgstr "下列异常主要被用作其他异常的基类。"

#: ../../library/exceptions.rst:77
msgid ""
"The base class for all built-in exceptions.  It is not meant to be directly "
"inherited by user-defined classes (for that, use :exc:`Exception`).  If :"
"func:`str` is called on an instance of this class, the representation of the "
"argument(s) to the instance are returned, or the empty string when there "
"were no arguments."
msgstr ""
"所有内置异常的基类。 它不应该被用户自定义类直接继承 (这种情况请使用 :exc:"
"`Exception`)。 如果在此类的实例上调用 :func:`str`，则会返回实例的参数表示，或"
"者当没有参数时返回空字符串。"

#: ../../library/exceptions.rst:85
msgid ""
"The tuple of arguments given to the exception constructor.  Some built-in "
"exceptions (like :exc:`OSError`) expect a certain number of arguments and "
"assign a special meaning to the elements of this tuple, while others are "
"usually called only with a single string giving an error message."
msgstr ""
"传给异常构造器的参数元组。 某些内置异常 (例如 :exc:`OSError`) 接受特定数量的"
"参数并赋予此元组中的元素特殊的含义，而其他异常通常只接受一个给出错误信息的单"
"独字符串。"

#: ../../library/exceptions.rst:92
msgid ""
"This method sets *tb* as the new traceback for the exception and returns the "
"exception object.  It is usually used in exception handling code like this::"
msgstr ""
"此方法将 *tb* 设为异常的新回溯信息并返回该异常对象。 它通常以如下的形式在异常"
"处理程序中使用::"

#: ../../library/exceptions.rst:105
msgid ""
"All built-in, non-system-exiting exceptions are derived from this class.  "
"All user-defined exceptions should also be derived from this class."
msgstr ""
"所有内置的非系统退出类异常都派生自此类。 所有用户自定义异常也应当派生自此类。"

#: ../../library/exceptions.rst:111
msgid ""
"The base class for those built-in exceptions that are raised for various "
"arithmetic errors: :exc:`OverflowError`, :exc:`ZeroDivisionError`, :exc:"
"`FloatingPointError`."
msgstr ""
"此基类用于派生针对各种算术类错误而引发的内置异常: :exc:`OverflowError`, :exc:"
"`ZeroDivisionError`, :exc:`FloatingPointError`。"

#: ../../library/exceptions.rst:118
msgid ""
"Raised when a :ref:`buffer <bufferobjects>` related operation cannot be "
"performed."
msgstr "当与 :ref:`缓冲区 <bufferobjects>` 相关的操作无法执行时将被引发。"

#: ../../library/exceptions.rst:124
msgid ""
"The base class for the exceptions that are raised when a key or index used "
"on a mapping or sequence is invalid: :exc:`IndexError`, :exc:`KeyError`.  "
"This can be raised directly by :func:`codecs.lookup`."
msgstr ""
"此基类用于派生当映射或序列所使用的键或索引无效时引发的异常: :exc:"
"`IndexError`, :exc:`KeyError`。 这可以通过 :func:`codecs.lookup` 来直接引发。"

#: ../../library/exceptions.rst:130
msgid "Concrete exceptions"
msgstr "具体异常"

#: ../../library/exceptions.rst:132
msgid "The following exceptions are the exceptions that are usually raised."
msgstr "以下异常属于经常被引发的异常。"

#: ../../library/exceptions.rst:138
msgid "Raised when an :keyword:`assert` statement fails."
msgstr "当 :keyword:`assert` 语句失败时将被引发。"

#: ../../library/exceptions.rst:143
msgid ""
"Raised when an attribute reference (see :ref:`attribute-references`) or "
"assignment fails.  (When an object does not support attribute references or "
"attribute assignments at all, :exc:`TypeError` is raised.)"
msgstr ""
"当属性引用 (参见 :ref:`attribute-references`) 或赋值失败时将被引发。 （当一个"
"对象根本不支持属性引用或属性赋值时则将引发 :exc:`TypeError`。）"

#: ../../library/exceptions.rst:150
msgid ""
"Raised when the :func:`input` function hits an end-of-file condition (EOF) "
"without reading any data. (N.B.: the :meth:`io.IOBase.read` and :meth:`io."
"IOBase.readline` methods return an empty string when they hit EOF.)"
msgstr ""
"当 :func:`input` 函数未读取任何数据即达到文件结束条件 (EOF) 时将被引发。 （另"
"外，:meth:`io.IOBase.read` 和 :meth:`io.IOBase.readline` 方法在遇到 EOF 则将"
"返回一个空字符串。）"

#: ../../library/exceptions.rst:157
msgid "Not currently used."
msgstr "目前未被使用。"

#: ../../library/exceptions.rst:162
msgid ""
"Raised when a :term:`generator` or :term:`coroutine` is closed; see :meth:"
"`generator.close` and :meth:`coroutine.close`.  It directly inherits from :"
"exc:`BaseException` instead of :exc:`Exception` since it is technically not "
"an error."
msgstr ""
"当一个 :term:`generator` 或 :term:`coroutine` 被关闭时将被引发；参见 :meth:"
"`generator.close` 和 :meth:`coroutine.close`。 它直接继承自 :exc:"
"`BaseException` 而不是 :exc:`Exception`，因为从技术上来说它并不是一个错误。"

#: ../../library/exceptions.rst:170
msgid ""
"Raised when the :keyword:`import` statement has troubles trying to load a "
"module.  Also raised when the \"from list\" in ``from ... import`` has a "
"name that cannot be found."
msgstr ""
"当 :keyword:`import` 语句尝试加载模块遇到麻烦时将被引发。 并且当 ``from ... "
"import`` 中的 \"from list\" 存在无法找到的名称时也会被引发。"

#: ../../library/exceptions.rst:174
msgid ""
"The :attr:`name` and :attr:`path` attributes can be set using keyword-only "
"arguments to the constructor. When set they represent the name of the module "
"that was attempted to be imported and the path to any file which triggered "
"the exception, respectively."
msgstr ""
":attr:`name` 与 :attr:`path` 属性可通过对构造器使用仅关键字参数来设定。 设定"
"后它们将分别表示被尝试导入的模块名称与触发异常的任意文件所在路径。"

#: ../../library/exceptions.rst:179
msgid "Added the :attr:`name` and :attr:`path` attributes."
msgstr "添加了 :attr:`name` 与 :attr:`path` 属性。"

#: ../../library/exceptions.rst:184
msgid ""
"A subclass of :exc:`ImportError` which is raised by :keyword:`import` when a "
"module could not be located.  It is also raised when ``None`` is found in :"
"data:`sys.modules`."
msgstr ""
":exc:`ImportError` 的子类，当一个模块无法被定位时将由 :keyword:`import` 引"
"发。 当在 :data:`sys.modules` 中找到 ``None`` 时也会被引发。"

#: ../../library/exceptions.rst:193
msgid ""
"Raised when a sequence subscript is out of range.  (Slice indices are "
"silently truncated to fall in the allowed range; if an index is not an "
"integer, :exc:`TypeError` is raised.)"
msgstr ""
"当序列抽取超出范围时将被引发。 （切片索引会被静默截短到允许的范围；如果指定索"
"引不是整数则 :exc:`TypeError` 会被引发。）"

#: ../../library/exceptions.rst:202
msgid ""
"Raised when a mapping (dictionary) key is not found in the set of existing "
"keys."
msgstr "当在现有键集合中找不到指定的映射（字典）键时将被引发。"

#: ../../library/exceptions.rst:209
msgid ""
"Raised when the user hits the interrupt key (normally :kbd:`Control-C` or :"
"kbd:`Delete`).  During execution, a check for interrupts is made regularly. "
"The exception inherits from :exc:`BaseException` so as to not be "
"accidentally caught by code that catches :exc:`Exception` and thus prevent "
"the interpreter from exiting."
msgstr ""
"当用户按下中断键 (通常为 :kbd:`Control-C` 或 :kbd:`Delete`) 时将被引发。 在执"
"行期间，会定期检测中断信号。 该异常继承自 :exc:`BaseException` 以确保不会被处"
"理 :exc:`Exception` 的代码意外捕获，这样可以避免退出解释器。"

#: ../../library/exceptions.rst:218
msgid ""
"Raised when an operation runs out of memory but the situation may still be "
"rescued (by deleting some objects).  The associated value is a string "
"indicating what kind of (internal) operation ran out of memory. Note that "
"because of the underlying memory management architecture (C's :c:func:"
"`malloc` function), the interpreter may not always be able to completely "
"recover from this situation; it nevertheless raises an exception so that a "
"stack traceback can be printed, in case a run-away program was the cause."
msgstr ""
"当一个操作耗尽内存但情况仍可（通过删除一些对象）进行挽救时将被引发。 关联的值"
"是一个字符串，指明是哪种（内部）操作耗尽了内存。 请注意由于底层的内存管理架构"
"（C 的 :c:func:`malloc` 函数），解释器也许并不总是能够从这种情况下完全恢复；"
"但它毕竟可以引发一个异常，这样就能打印出栈回溯信息，以便找出导致问题的失控程"
"序。"

#: ../../library/exceptions.rst:229
msgid ""
"Raised when a local or global name is not found.  This applies only to "
"unqualified names.  The associated value is an error message that includes "
"the name that could not be found."
msgstr ""
"当某个局部或全局名称未找到时将被引发。 此异常仅用于非限定名称。 关联的值是一"
"条错误信息，其中包含未找到的名称。"

#: ../../library/exceptions.rst:236
msgid ""
"This exception is derived from :exc:`RuntimeError`.  In user defined base "
"classes, abstract methods should raise this exception when they require "
"derived classes to override the method, or while the class is being "
"developed to indicate that the real implementation still needs to be added."
msgstr ""
"此异常派生自 :exc:`RuntimeError`。 在用户自定义的基类中，抽象方法应当在其要求"
"所派生类重载该方法，或是在其要求所开发的类提示具体实现尚待添加时引发此异常。"

#: ../../library/exceptions.rst:243
msgid ""
"It should not be used to indicate that an operator or method is not meant to "
"be supported at all -- in that case either leave the operator / method "
"undefined or, if a subclass, set it to :data:`None`."
msgstr ""
"它不应当用来表示一个运算符或方法根本不能被支持 -- 在此情况下应当让特定运算"
"符 / 方法保持未定义，或者在子类中将其设为 :data:`None`。"

#: ../../library/exceptions.rst:249
msgid ""
"``NotImplementedError`` and ``NotImplemented`` are not interchangeable, even "
"though they have similar names and purposes.  See :data:`NotImplemented` for "
"details on when to use it."
msgstr ""
"``NotImplementedError`` 和 ``NotImplemented`` 不可互换，即使它们有相似的名称"
"和用途。 请参阅 :data:`NotImplemented` 了解有关何时使用它们的详细说明。"

#: ../../library/exceptions.rst:258
msgid ""
"This exception is raised when a system function returns a system-related "
"error, including I/O failures such as \"file not found\" or \"disk "
"full\" (not for illegal argument types or other incidental errors)."
msgstr ""
"此异常在一个系统函数返回系统相关的错误时将被引发，此类错误包括 I/O 操作失败例"
"如 \"文件未找到\" 或 \"磁盘已满\" 等（不包括非法参数类型或其他偶然性错误）。"

#: ../../library/exceptions.rst:262
msgid ""
"The second form of the constructor sets the corresponding attributes, "
"described below.  The attributes default to :const:`None` if not specified.  "
"For backwards compatibility, if three arguments are passed, the :attr:"
"`~BaseException.args` attribute contains only a 2-tuple of the first two "
"constructor arguments."
msgstr ""
"构造器的第二种形式可设置如下所述的相应属性。 如果未指定这些属性则默认为 :"
"const:`None`。 为了能向下兼容，如果传入了三个参数，则 :attr:`~BaseException."
"args` 属性将仅包含由前两个构造器参数组成的 2 元组。"

#: ../../library/exceptions.rst:268
msgid ""
"The constructor often actually returns a subclass of :exc:`OSError`, as "
"described in `OS exceptions`_ below.  The particular subclass depends on the "
"final :attr:`.errno` value.  This behaviour only occurs when constructing :"
"exc:`OSError` directly or via an alias, and is not inherited when "
"subclassing."
msgstr ""
"构造器实际返回的往往是 :exc:`OSError` 的某个子类，如下文 `OS exceptions`_ 中"
"所描述的。 具体的子类取决于最终的 :attr:`.errno` 值。 此行为仅在直接或通过别"
"名来构造 :exc:`OSError` 时发生，并且在子类化时不会被继承。"

#: ../../library/exceptions.rst:276
msgid "A numeric error code from the C variable :c:data:`errno`."
msgstr "来自于 C 变量 :c:data:`errno` 的数字错误码。"

#: ../../library/exceptions.rst:280
msgid ""
"Under Windows, this gives you the native Windows error code.  The :attr:`."
"errno` attribute is then an approximate translation, in POSIX terms, of that "
"native error code."
msgstr ""
"在 Windows 下，此参数将给出原生的 Windows 错误码。 而 :attr:`.errno` 属性将是"
"该原生错误码在 POSIX 平台下的近似转换形式。"

#: ../../library/exceptions.rst:284
msgid ""
"Under Windows, if the *winerror* constructor argument is an integer, the :"
"attr:`.errno` attribute is determined from the Windows error code, and the "
"*errno* argument is ignored.  On other platforms, the *winerror* argument is "
"ignored, and the :attr:`winerror` attribute does not exist."
msgstr ""
"在 Windows 下，如果 *winerror* 构造器参数是一个整数，则 :attr:`.errno` 属性会"
"根据 Windows 错误码来确定，而 *errno* 参数会被忽略。 在其他平台上，"
"*winerror* 参数会被忽略，并且 :attr:`winerror` 属性将不存在。"

#: ../../library/exceptions.rst:292
msgid ""
"The corresponding error message, as provided by the operating system.  It is "
"formatted by the C functions :c:func:`perror` under POSIX, and :c:func:"
"`FormatMessage` under Windows."
msgstr ""
"操作系统所提供的相应错误信息。 它在 POSIX 平台中由 C 函数 :c:func:`perror` 来"
"格式化，在 Windows 中则是由 :c:func:`FormatMessage`。"

#: ../../library/exceptions.rst:300
msgid ""
"For exceptions that involve a file system path (such as :func:`open` or :"
"func:`os.unlink`), :attr:`filename` is the file name passed to the function. "
"For functions that involve two file system paths (such as :func:`os."
"rename`), :attr:`filename2` corresponds to the second file name passed to "
"the function."
msgstr ""
"对于与文件系统路径有关 (例如 :func:`open` 或 :func:`os.unlink`) 的异常，:"
"attr:`filename` 是传给函数的文件名。 对于涉及两个文件系统路径的函数 (例如 :"
"func:`os.rename`)，:attr:`filename2` 将是传给函数的第二个文件名。"

#: ../../library/exceptions.rst:307
msgid ""
":exc:`EnvironmentError`, :exc:`IOError`, :exc:`WindowsError`, :exc:`socket."
"error`, :exc:`select.error` and :exc:`mmap.error` have been merged into :exc:"
"`OSError`, and the constructor may return a subclass."
msgstr ""
":exc:`EnvironmentError`, :exc:`IOError`, :exc:`WindowsError`, :exc:`socket."
"error`, :exc:`select.error` 与 :exc:`mmap.error` 已被合并到 :exc:`OSError`，"
"构造器可能返回其中一个子类。"

#: ../../library/exceptions.rst:313
msgid ""
"The :attr:`filename` attribute is now the original file name passed to the "
"function, instead of the name encoded to or decoded from the filesystem "
"encoding.  Also, the *filename2* constructor argument and attribute was "
"added."
msgstr ""
":attr:`filename` 属性现在将是传给函数的原始文件名，而不是经过编码或基于文件系"
"统编码进行解码之后的名称。 此外还添加了 *filename2* 构造器参数和属性。"

#: ../../library/exceptions.rst:322
msgid ""
"Raised when the result of an arithmetic operation is too large to be "
"represented.  This cannot occur for integers (which would rather raise :exc:"
"`MemoryError` than give up).  However, for historical reasons, OverflowError "
"is sometimes raised for integers that are outside a required range.   "
"Because of the lack of standardization of floating point exception handling "
"in C, most floating point operations are not checked."
msgstr ""
"当算术运算的结果大到无法表示时将被引发。 这对整数来说不可能发生（宁可引发 :"
"exc:`MemoryError` 也不会放弃尝试）。 但是出于历史原因，有时也会在整数超出要求"
"范围的情况下引发 OverflowError。 因为在 C 中缺少对浮点异常处理的标准化，大多"
"数浮点运算都不会做检查。"

#: ../../library/exceptions.rst:332
msgid ""
"This exception is derived from :exc:`RuntimeError`.  It is raised when the "
"interpreter detects that the maximum recursion depth (see :func:`sys."
"getrecursionlimit`) is exceeded."
msgstr ""
"此异常派生自 :exc:`RuntimeError`。 它会在解释器检测发现超过最大递归深度 (参"
"见 :func:`sys.getrecursionlimit`) 时被引发。"

#: ../../library/exceptions.rst:336
msgid "Previously, a plain :exc:`RuntimeError` was raised."
msgstr "在此之前将只引发 :exc:`RuntimeError`。"

#: ../../library/exceptions.rst:342
msgid ""
"This exception is raised when a weak reference proxy, created by the :func:"
"`weakref.proxy` function, is used to access an attribute of the referent "
"after it has been garbage collected. For more information on weak "
"references, see the :mod:`weakref` module."
msgstr ""
"此异常将在使用 :func:`weakref.proxy` 函数所创建的弱引用来访问该引用的某个已被"
"作为垃圾回收的属性时被引发。 有关弱引用的更多信息请参阅 :mod:`weakref` 模块。"

#: ../../library/exceptions.rst:350
msgid ""
"Raised when an error is detected that doesn't fall in any of the other "
"categories.  The associated value is a string indicating what precisely went "
"wrong."
msgstr ""
"当检测到一个不归属于任何其他类别的错误时将被引发。 关联的值是一个指明究竟发生"
"了什么问题的字符串。"

#: ../../library/exceptions.rst:357
msgid ""
"Raised by built-in function :func:`next` and an :term:`iterator`\\'s :meth:"
"`~iterator.__next__` method to signal that there are no further items "
"produced by the iterator."
msgstr ""
"由内置函数 :func:`next` 和 :term:`iterator` 的 :meth:`~iterator.__next__` 方"
"法所引发，用来表示该迭代器不能产生下一项。"

#: ../../library/exceptions.rst:361
msgid ""
"The exception object has a single attribute :attr:`value`, which is given as "
"an argument when constructing the exception, and defaults to :const:`None`."
msgstr ""
"该异常对象只有一个属性 :attr:`value`，它在构造该异常时作为参数给出，默认值"
"为 :const:`None`。"

#: ../../library/exceptions.rst:365
msgid ""
"When a :term:`generator` or :term:`coroutine` function returns, a new :exc:"
"`StopIteration` instance is raised, and the value returned by the function "
"is used as the :attr:`value` parameter to the constructor of the exception."
msgstr ""
"当一个 :term:`generator` 或 :term:`coroutine` 函数返回时，将引发一个新的 :"
"exc:`StopIteration` 实例，函数返回的值将被用作异常构造器的 :attr:`value` 形"
"参。"

#: ../../library/exceptions.rst:370
msgid ""
"If a generator code directly or indirectly raises :exc:`StopIteration`, it "
"is converted into a :exc:`RuntimeError` (retaining the :exc:`StopIteration` "
"as the new exception's cause)."
msgstr ""
"如果某个生成器代码直接或间接地引发了 :exc:`StopIteration`，它会被转换为 :exc:"
"`RuntimeError` (并将 :exc:`StopIteration` 保留为导致新异常的原因)。"

#: ../../library/exceptions.rst:374
msgid ""
"Added ``value`` attribute and the ability for generator functions to use it "
"to return a value."
msgstr "添加了 ``value`` 属性及其被生成器函数用作返回值的功能。"

#: ../../library/exceptions.rst:378
msgid ""
"Introduced the RuntimeError transformation via ``from __future__ import "
"generator_stop``, see :pep:`479`."
msgstr ""
"引入了通过 ``from __future__ import generator_stop`` 来实现 RuntimeError 转"
"换，参见 :pep:`479`。"

#: ../../library/exceptions.rst:382
msgid ""
"Enable :pep:`479` for all code by default: a :exc:`StopIteration` error "
"raised in a generator is transformed into a :exc:`RuntimeError`."
msgstr ""
"默认对所有代码启用 :pep:`479`: 在生成器中引发的 :exc:`StopIteration` 错误将被"
"转换为 :exc:`RuntimeError`。"

#: ../../library/exceptions.rst:388
msgid ""
"Must be raised by :meth:`__anext__` method of an :term:`asynchronous "
"iterator` object to stop the iteration."
msgstr ""
"必须由一个 :term:`asynchronous iterator` 对象的 :meth:`__anext__` 方法来引发"
"以停止迭代操作。"

#: ../../library/exceptions.rst:395
msgid ""
"Raised when the parser encounters a syntax error.  This may occur in an :"
"keyword:`import` statement, in a call to the built-in functions :func:`exec` "
"or :func:`eval`, or when reading the initial script or standard input (also "
"interactively)."
msgstr ""
"当解析器遇到语法错误时将被引发。 这可以发生在 :keyword:`import` 语句，对内置"
"函数 :func:`exec` 或 :func:`eval` 的调用，或者读取原始脚本或标准输入（也包括"
"交互模式）的时候。"

#: ../../library/exceptions.rst:400
msgid ""
"The :func:`str` of the exception instance returns only the error message."
msgstr "异常实例的 :func:`str` 只返回错误消息。"

#: ../../library/exceptions.rst:404
msgid "The name of the file the syntax error occurred in."
msgstr "发生语法错误所在文件的名称。"

#: ../../library/exceptions.rst:408
msgid ""
"Which line number in the file the error occurred in. This is 1-indexed: the "
"first line in the file has a ``lineno`` of 1."
msgstr ""
"发生错误所在文件中的行号。  行号索引从 1 开始：文件中首行的 ``lineno`` 为 1。"

#: ../../library/exceptions.rst:413
msgid ""
"The column in the line where the error occurred. This is 1-indexed: the "
"first character in the line has an ``offset`` of 1."
msgstr ""
"发生错误所在文件中的列号。 列号索引从 1 开始：行中首个字符的 ``offset`` 为 "
"1。"

#: ../../library/exceptions.rst:418
msgid "The source code text involved in the error."
msgstr "错误所涉及的源代码文本。"

#: ../../library/exceptions.rst:423
msgid ""
"Base class for syntax errors related to incorrect indentation.  This is a "
"subclass of :exc:`SyntaxError`."
msgstr ""
"与不正确的缩进相关的语法错误的基类。 这是 :exc:`SyntaxError` 的一个子类。"

#: ../../library/exceptions.rst:429
msgid ""
"Raised when indentation contains an inconsistent use of tabs and spaces. "
"This is a subclass of :exc:`IndentationError`."
msgstr ""
"当缩进包含对制表符和空格符不一致的使用时将被引发。 这是 :exc:"
"`IndentationError` 的一个子类。"

#: ../../library/exceptions.rst:435
msgid ""
"Raised when the interpreter finds an internal error, but the situation does "
"not look so serious to cause it to abandon all hope. The associated value is "
"a string indicating what went wrong (in low-level terms)."
msgstr ""
"当解释器发现内部错误，但情况看起来尚未严重到要放弃所有希望时将被引发。 关联的"
"值是一个指明发生了什么问题的字符串（表示为低层级的符号）。"

#: ../../library/exceptions.rst:439
msgid ""
"You should report this to the author or maintainer of your Python "
"interpreter. Be sure to report the version of the Python interpreter (``sys."
"version``; it is also printed at the start of an interactive Python "
"session), the exact error message (the exception's associated value) and if "
"possible the source of the program that triggered the error."
msgstr ""
"你应当将此问题报告给你所用 Python 解释器的作者或维护人员。 请确认报告 Python "
"解释器的版本号 (``sys.version``; 它也会在交互式 Python 会话开始时被打印出"
"来)，具体的错误消息（异常所关联的值）以及可能触发该错误的程序源码。"

#: ../../library/exceptions.rst:448
msgid ""
"This exception is raised by the :func:`sys.exit` function.  It inherits "
"from :exc:`BaseException` instead of :exc:`Exception` so that it is not "
"accidentally caught by code that catches :exc:`Exception`.  This allows the "
"exception to properly propagate up and cause the interpreter to exit.  When "
"it is not handled, the Python interpreter exits; no stack traceback is "
"printed.  The constructor accepts the same optional argument passed to :func:"
"`sys.exit`. If the value is an integer, it specifies the system exit status "
"(passed to C's :c:func:`exit` function); if it is ``None``, the exit status "
"is zero; if it has another type (such as a string), the object's value is "
"printed and the exit status is one."
msgstr ""
"此异常由 :func:`sys.exit` 函数引发。 它继承自 :exc:`BaseException` 而不是 :"
"exc:`Exception` 以确保不会被处理 :exc:`Exception` 的代码意外捕获。 这允许此异"
"常正确地向上传播并导致解释器退出。 如果它未被处理，则 Python 解释器就将退出；"
"不会打印任何栈回溯信息。 构造器接受的可选参数与传递给 :func:`sys.exit` 的相"
"同。 如果该值为一个整数，则它指明系统退出状态码（会传递给 C 的 :c:func:"
"`exit` 函数）；如果该值为 ``None``，则退出状态码为零；如果该值为其他类型（例"
"如字符串），则会打印对象的值并将退出状态码设为一。"

#: ../../library/exceptions.rst:459
msgid ""
"A call to :func:`sys.exit` is translated into an exception so that clean-up "
"handlers (:keyword:`finally` clauses of :keyword:`try` statements) can be "
"executed, and so that a debugger can execute a script without running the "
"risk of losing control.  The :func:`os._exit` function can be used if it is "
"absolutely positively necessary to exit immediately (for example, in the "
"child process after a call to :func:`os.fork`)."
msgstr ""
"对 :func:`sys.exit` 的调用会被转换为一个异常以便能执行清理处理程序 (:keyword:"
"`try` 语句的 :keyword:`finally` 子句)，并且使得调试器可以执行一段脚本而不必冒"
"失去控制的风险。 如果绝对确实地需要立即退出（例如在调用 :func:`os.fork` 之后"
"的子进程中）则可使用 :func:`os._exit`."

#: ../../library/exceptions.rst:468
msgid ""
"The exit status or error message that is passed to the constructor. "
"(Defaults to ``None``.)"
msgstr "传给构造器的退出状态码或错误信息（默认为 ``None``。）"

#: ../../library/exceptions.rst:474
msgid ""
"Raised when an operation or function is applied to an object of "
"inappropriate type.  The associated value is a string giving details about "
"the type mismatch."
msgstr ""
"当一个操作或函数被应用于类型不适当的对象时将被引发。 关联的值是一个字符串，给"
"出有关类型不匹配的详情。"

#: ../../library/exceptions.rst:477
msgid ""
"This exception may be raised by user code to indicate that an attempted "
"operation on an object is not supported, and is not meant to be. If an "
"object is meant to support a given operation but has not yet provided an "
"implementation, :exc:`NotImplementedError` is the proper exception to raise."
msgstr ""
"此异常可以由用户代码引发，以表明尝试对某个对象进行的操作不受支持也不应当受支"
"持。 如果某个对象应当支持给定的操作但尚未提供相应的实现，所要引发的适当异常应"
"为 :exc:`NotImplementedError`。"

#: ../../library/exceptions.rst:482
msgid ""
"Passing arguments of the wrong type (e.g. passing a :class:`list` when an :"
"class:`int` is expected) should result in a :exc:`TypeError`, but passing "
"arguments with the wrong value (e.g. a number outside expected boundaries) "
"should result in a :exc:`ValueError`."
msgstr ""
"传入参数的类型错误 (例如在要求 :class:`int` 时却传入了 :class:`list`) 应当导"
"致 :exc:`TypeError`，但传入参数的值错误 (例如传入要求范围之外的数值) 则应当导"
"致 :exc:`ValueError`。"

#: ../../library/exceptions.rst:489
msgid ""
"Raised when a reference is made to a local variable in a function or method, "
"but no value has been bound to that variable.  This is a subclass of :exc:"
"`NameError`."
msgstr ""
"当在函数或方法中对某个局部变量进行引用，但该变量并未绑定任何值时将被引发。 此"
"异常是 :exc:`NameError` 的一个子类。"

#: ../../library/exceptions.rst:496
msgid ""
"Raised when a Unicode-related encoding or decoding error occurs.  It is a "
"subclass of :exc:`ValueError`."
msgstr ""
"当发生与 Unicode 相关的编码或解码错误时将被引发。 此异常是 :exc:`ValueError` "
"的一个子类。"

#: ../../library/exceptions.rst:499
msgid ""
":exc:`UnicodeError` has attributes that describe the encoding or decoding "
"error.  For example, ``err.object[err.start:err.end]`` gives the particular "
"invalid input that the codec failed on."
msgstr ""
":exc:`UnicodeError` 具有一些描述编码或解码错误的属性。 例如 ``err.object[err."
"start:err.end]`` 会给出导致编解码器失败的特定无效输入。"

#: ../../library/exceptions.rst:505
msgid "The name of the encoding that raised the error."
msgstr "引发错误的编码名称。"

#: ../../library/exceptions.rst:509
msgid "A string describing the specific codec error."
msgstr "描述特定编解码器错误的字符串。"

#: ../../library/exceptions.rst:513
msgid "The object the codec was attempting to encode or decode."
msgstr "编解码器试图要编码或解码的对象。"

#: ../../library/exceptions.rst:517
msgid "The first index of invalid data in :attr:`object`."
msgstr ":attr:`object` 中无效数据的开始位置索引。"

#: ../../library/exceptions.rst:521
msgid "The index after the last invalid data in :attr:`object`."
msgstr ":attr:`object` 中无效数据的末尾位置索引（不含）。"

#: ../../library/exceptions.rst:526
msgid ""
"Raised when a Unicode-related error occurs during encoding.  It is a "
"subclass of :exc:`UnicodeError`."
msgstr ""
"当在编码过程中发生与 Unicode 相关的错误时将被引发。 此异常是 :exc:"
"`UnicodeError` 的一个子类。"

#: ../../library/exceptions.rst:532
msgid ""
"Raised when a Unicode-related error occurs during decoding.  It is a "
"subclass of :exc:`UnicodeError`."
msgstr ""
"当在解码过程中发生与 Unicode 相关的错误时将被引发。 此异常是 :exc:"
"`UnicodeError` 的一个子类。"

#: ../../library/exceptions.rst:538
msgid ""
"Raised when a Unicode-related error occurs during translating.  It is a "
"subclass of :exc:`UnicodeError`."
msgstr ""
"在转写过程中发生与 Unicode 相关的错误时将被引发。 此异常是 :exc:"
"`UnicodeError` 的一个子类。"

#: ../../library/exceptions.rst:544
msgid ""
"Raised when an operation or function receives an argument that has the right "
"type but an inappropriate value, and the situation is not described by a "
"more precise exception such as :exc:`IndexError`."
msgstr ""
"当操作或函数接收到具有正确类型但值不适合的参数，并且情况不能用更精确的异常例"
"如 :exc:`IndexError` 来描述时将被引发。"

#: ../../library/exceptions.rst:551
msgid ""
"Raised when the second argument of a division or modulo operation is zero.  "
"The associated value is a string indicating the type of the operands and the "
"operation."
msgstr ""
"当除法或取余运算的第二个参数为零时将被引发。 关联的值是一个字符串，指明操作数"
"和运算的类型。"

#: ../../library/exceptions.rst:556
msgid ""
"The following exceptions are kept for compatibility with previous versions; "
"starting from Python 3.3, they are aliases of :exc:`OSError`."
msgstr ""
"下列异常被保留以与之前的版本相兼容；从 Python 3.3 开始，它们都是 :exc:"
"`OSError` 的别名。"

#: ../../library/exceptions.rst:565
msgid "Only available on Windows."
msgstr "限在 Windows 中可用。"

#: ../../library/exceptions.rst:569
msgid "OS exceptions"
msgstr "OS 异常"

#: ../../library/exceptions.rst:571
msgid ""
"The following exceptions are subclasses of :exc:`OSError`, they get raised "
"depending on the system error code."
msgstr "下列异常均为 :exc:`OSError` 的子类，它们将根据系统错误代码被引发。"

#: ../../library/exceptions.rst:576
msgid ""
"Raised when an operation would block on an object (e.g. socket) set for non-"
"blocking operation. Corresponds to :c:data:`errno` ``EAGAIN``, ``EALREADY``, "
"``EWOULDBLOCK`` and ``EINPROGRESS``."
msgstr ""
"当一个操作会被某个设置为非阻塞操作的对象（例如套接字）所阻塞时将被引发。 对应"
"于 :c:data:`errno` ``EAGAIN``, ``EALREADY``, ``EWOULDBLOCK`` 和 "
"``EINPROGRESS``。"

#: ../../library/exceptions.rst:581
msgid ""
"In addition to those of :exc:`OSError`, :exc:`BlockingIOError` can have one "
"more attribute:"
msgstr ""
"除了 :exc:`OSError` 已有的属性，:exc:`BlockingIOError` 还有一个额外属性："

#: ../../library/exceptions.rst:586
msgid ""
"An integer containing the number of characters written to the stream before "
"it blocked.  This attribute is available when using the buffered I/O classes "
"from the :mod:`io` module."
msgstr ""
"一个整数，表示在被阻塞前已写入到流的字符数。 当使用来自 :mod:`io` 模块的带缓"
"冲 I/O 类时此属性可用。"

#: ../../library/exceptions.rst:592
msgid ""
"Raised when an operation on a child process failed. Corresponds to :c:data:"
"`errno` ``ECHILD``."
msgstr ""
"当一个子进程上的操作失败时将被引发。 对应于 :c:data:`errno` ``ECHILD``。"

#: ../../library/exceptions.rst:597
msgid "A base class for connection-related issues."
msgstr "与连接相关问题的基类。"

#: ../../library/exceptions.rst:599
msgid ""
"Subclasses are :exc:`BrokenPipeError`, :exc:`ConnectionAbortedError`, :exc:"
"`ConnectionRefusedError` and :exc:`ConnectionResetError`."
msgstr ""
"其子类有 :exc:`BrokenPipeError`, :exc:`ConnectionAbortedError`, :exc:"
"`ConnectionRefusedError` 和 :exc:`ConnectionResetError`。"

#: ../../library/exceptions.rst:604
msgid ""
"A subclass of :exc:`ConnectionError`, raised when trying to write on a pipe "
"while the other end has been closed, or trying to write on a socket which "
"has been shutdown for writing. Corresponds to :c:data:`errno` ``EPIPE`` and "
"``ESHUTDOWN``."
msgstr ""
":exc:`ConnectionError` 的子类，当试图写入另一端已被关闭的管道，或是试图写入已"
"关闭写入的套接字时将被引发。 对应于 :c:data:`errno` ``EPIPE`` 和 "
"``ESHUTDOWN``。"

#: ../../library/exceptions.rst:611
msgid ""
"A subclass of :exc:`ConnectionError`, raised when a connection attempt is "
"aborted by the peer. Corresponds to :c:data:`errno` ``ECONNABORTED``."
msgstr ""
":exc:`ConnectionError` 的子类，当连接尝试被对端中止时将被引发。 对应于 :c:"
"data:`errno` ``ECONNABORTED``。"

#: ../../library/exceptions.rst:617
msgid ""
"A subclass of :exc:`ConnectionError`, raised when a connection attempt is "
"refused by the peer. Corresponds to :c:data:`errno` ``ECONNREFUSED``."
msgstr ""
":exc:`ConnectionError` 的子类，当连接尝试被对端拒绝时将被引发。 对应于 :c:"
"data:`errno` ``ECONNREFUSED``。"

#: ../../library/exceptions.rst:623
msgid ""
"A subclass of :exc:`ConnectionError`, raised when a connection is reset by "
"the peer. Corresponds to :c:data:`errno` ``ECONNRESET``."
msgstr ""
":exc:`ConnectionError` 的子类，当连接被对端重置时将被引发。 对应于 :c:data:"
"`errno` ``ECONNRESET``。"

#: ../../library/exceptions.rst:629
msgid ""
"Raised when trying to create a file or directory which already exists. "
"Corresponds to :c:data:`errno` ``EEXIST``."
msgstr ""
"当试图创建一个已存在的文件或目录时将被引发。 对应于 :c:data:`errno` "
"``EEXIST``。"

#: ../../library/exceptions.rst:634
msgid ""
"Raised when a file or directory is requested but doesn't exist. Corresponds "
"to :c:data:`errno` ``ENOENT``."
msgstr ""
"当所请求的文件或目录不存在时将被引发。 对应于 :c:data:`errno` ``ENOENT``。"

#: ../../library/exceptions.rst:639
msgid ""
"Raised when a system call is interrupted by an incoming signal. Corresponds "
"to :c:data:`errno` :py:data:`~errno.EINTR`."
msgstr ""
"当系统调用被输入信号中断时将被引发。 对应于 :c:data:`errno` :py:data:`~errno."
"EINTR`。"

#: ../../library/exceptions.rst:642
msgid ""
"Python now retries system calls when a syscall is interrupted by a signal, "
"except if the signal handler raises an exception (see :pep:`475` for the "
"rationale), instead of raising :exc:`InterruptedError`."
msgstr ""
"当系统调用被某个信号中断时，Python 现在会重试系统调用，除非该信号的处理程序引"
"发了其它异常 (原理参见 :pep:`475`) 而不是引发 :exc:`InterruptedError`。"

#: ../../library/exceptions.rst:649
msgid ""
"Raised when a file operation (such as :func:`os.remove`) is requested on a "
"directory. Corresponds to :c:data:`errno` ``EISDIR``."
msgstr ""
"当请求对一个目录执行文件操作 (例如 :func:`os.remove`) 将被引发。 对应于 :c:"
"data:`errno` ``EISDIR``。"

#: ../../library/exceptions.rst:655
msgid ""
"Raised when a directory operation (such as :func:`os.listdir`) is requested "
"on something which is not a directory. Corresponds to :c:data:`errno` "
"``ENOTDIR``."
msgstr ""
"当请求对一个非目录对象执行目录操作 (例如 :func:`os.listdir`) 时将被引发。 对"
"应于 :c:data:`errno` ``ENOTDIR``。"

#: ../../library/exceptions.rst:661
msgid ""
"Raised when trying to run an operation without the adequate access rights - "
"for example filesystem permissions. Corresponds to :c:data:`errno` "
"``EACCES`` and ``EPERM``."
msgstr ""
"当在没有足够操作权限的情况下试图执行某个操作时将被引发 —— 例如缺少文件系统权"
"限。 对应于 :c:data:`errno` ``EACCES`` 和 ``EPERM``。"

#: ../../library/exceptions.rst:667
msgid ""
"Raised when a given process doesn't exist. Corresponds to :c:data:`errno` "
"``ESRCH``."
msgstr "当给定的进程不存在时将被引发。 对应于 :c:data:`errno` ``ESRCH``。"

#: ../../library/exceptions.rst:672
msgid ""
"Raised when a system function timed out at the system level. Corresponds to :"
"c:data:`errno` ``ETIMEDOUT``."
msgstr ""
"当一个系统函数发生系统级超时的情况下将被引发。 对应于 :c:data:`errno` "
"``ETIMEDOUT``。"

#: ../../library/exceptions.rst:675
msgid "All the above :exc:`OSError` subclasses were added."
msgstr "添加了以上所有 :exc:`OSError` 的子类。"

#: ../../library/exceptions.rst:681
msgid ":pep:`3151` - Reworking the OS and IO exception hierarchy"
msgstr ":pep:`3151` - 重写 OS 和 IO 异常的层次结构"

#: ../../library/exceptions.rst:687
msgid "Warnings"
msgstr "警告"

#: ../../library/exceptions.rst:689
msgid ""
"The following exceptions are used as warning categories; see the :ref:"
"`warning-categories` documentation for more details."
msgstr ""
"下列异常被用作警告类别；请参阅 :ref:`warning-categories` 文档了解详情。"

#: ../../library/exceptions.rst:694
msgid "Base class for warning categories."
msgstr "警告类别的基类。"

#: ../../library/exceptions.rst:699
msgid "Base class for warnings generated by user code."
msgstr "用户代码所产生警告的基类。"

#: ../../library/exceptions.rst:704
msgid ""
"Base class for warnings about deprecated features when those warnings are "
"intended for other Python developers."
msgstr ""
"如果所发出的警告是针对其他 Python 开发者的，则以此作为与已弃用特性相关警告的"
"基类。"

#: ../../library/exceptions.rst:710
msgid ""
"Base class for warnings about features which are obsolete and expected to be "
"deprecated in the future, but are not deprecated at the moment."
msgstr "对于已过时并预计在未来弃用，但目前尚未弃用的特性相关警告的基类。"

#: ../../library/exceptions.rst:714
msgid ""
"This class is rarely used as emitting a warning about a possible upcoming "
"deprecation is unusual, and :exc:`DeprecationWarning` is preferred for "
"already active deprecations."
msgstr ""
"这个类很少被使用，因为针对未来可能的弃用发出警告的做法并不常见，而针对当前已"
"有的弃用则推荐使用 :exc:`DeprecationWarning`。"

#: ../../library/exceptions.rst:721
msgid "Base class for warnings about dubious syntax."
msgstr "与模糊的语法相关的警告的基类。"

#: ../../library/exceptions.rst:726
msgid "Base class for warnings about dubious runtime behavior."
msgstr "与模糊的运行时行为相关的警告的基类。"

#: ../../library/exceptions.rst:731
msgid ""
"Base class for warnings about deprecated features when those warnings are "
"intended for end users of applications that are written in Python."
msgstr ""
"如果所发出的警告是针对以 Python 所编写应用的最终用户的，则以此作为与已弃用特"
"性相关警告的基类。"

#: ../../library/exceptions.rst:737
msgid "Base class for warnings about probable mistakes in module imports."
msgstr "与在模块导入中可能的错误相关的警告的基类。"

#: ../../library/exceptions.rst:742
msgid "Base class for warnings related to Unicode."
msgstr "与 Unicode 相关的警告的基类。"

#: ../../library/exceptions.rst:747
msgid ""
"Base class for warnings related to :class:`bytes` and :class:`bytearray`."
msgstr "与 :class:`bytes` 和 :class:`bytearray` 相关的警告的基类。"

#: ../../library/exceptions.rst:752
msgid ""
"Base class for warnings related to resource usage. Ignored by the default "
"warning filters."
msgstr "与资源使用相关的警告的基类。 会被默认的警告过滤器忽略。"

#: ../../library/exceptions.rst:760
msgid "Exception hierarchy"
msgstr "异常层次结构"

#: ../../library/exceptions.rst:762
msgid "The class hierarchy for built-in exceptions is:"
msgstr "内置异常的类层级结构如下："
